Workbook
Name Slicer_Bank_Name: #N/A
Name Slicer_Gender: #N/A
Name Slicer_State: #N/A

Sheet data
A1: Transaction_ID | B1: Transaction_Date | C1: Day | D1: Transaction_Time | E1: hour | F1: UPI_App | G1: Customer_ID | H1: Age_Group | I1: Gender | J1: State | K1: City | L1: Merchant_Name | M1: Merchant_Category | N1: Transaction_Type | O1: Payment_Mode | P1: Bank_Name | Q1: Amount_INR | R1: Cashback_INR | S1: Transaction_Fee_INR | T1: Status | U1: Failure_Reason | V1: Device_OS | W1: Risk_Score | X1: Is_Suspected_Fraud
A2: UPI202605P2_0000001 | B2: 46170 | C2: =TEXT(Table3[[#This Row],[Transaction_Date]],"dddd") -> Thursday | D2: 17:01:47 | E2: =HOUR(Table3[[#This Row],[Transaction_Time]]) -> 17 | F2: PhonePe | G2: CUST882856 | H2: 25-34 | I2: Male | J2: Telangana | K2: Warangal | L2: Topmate | M2: Education | N2: P2P | O2: Bank Account | P2: Bank of Baroda | Q2: 572.53 | R2: 51.8 | S2: 0 | T2: Success | V2: iOS | W2: 7 | X2: No
A3: UPI202605P2_0000002 | B3: 46152 | C3: =TEXT(Table3[[#This Row],[Transaction_Date]],"dddd") -> Sunday | D3: 12:14:08 | E3: =HOUR(Table3[[#This Row],[Transaction_Time]]) -> 12 | F3: Google Pay | G3: CUST170502 | H3: 25-34 | I3: Female | J3: Tamil Nadu | K3: Chennai | L3: Udemy | M3: Education | N3: P2M | O3: UPI ID | P3: Axis Bank | Q3: 415.75 | R3: 0 | S3: 0 | T3: Success | V3: Android | W3: 72 | X3: No
A4: UPI202605P2_0000003 | B4: 46146 | C4: =TEXT(Table3[[#This Row],[Transaction_Date]],"dddd") -> Monday | D4: 19:43:47 | E4: =HOUR(Table3[[#This Row],[Transaction_Time]]) -> 19 | F4: Paytm | G4: CUST107673 | H4: 35-44 | I4: Male | J4: Delhi | K4: New Delhi | L4: Local Clinic | M4: Healthcare | N4: Bill Payment | O4: QR Scan | P4: Punjab National Bank | Q4: 1007.05 | R4: 22.81 | S4: 0 | T4: Success | V4: Android | W4: 29 | X4: No
A5: UPI202605P2_0000004 | B5: 46156 | C5: =TEXT(Table3[[#This Row],[Transaction_Date]],"dddd") -> Thursday | D5: 20:05:37 | E5: =HOUR(Table3[[#This Row],[Transaction_Time]]) -> 20 | F5: PhonePe | G5: CUST817281 | H5: 35-44 | I5: Female | J5: Telangana | K5: Nizamabad | L5: Indian Oil | M5: Fuel | N5: P2M | O5: QR Scan | P5: HDFC Bank | Q5: 390.86 | R5: 0 | S5: 0 | T5: Success | V5: Android | W5: 93 | X5: Yes
A6: UPI202605P2_0000005 | B6: 46153 | C6: =TEXT(Table3[[#This Row],[Transaction_Date]],"dddd") -> Monday | D6: 14:01:05 | E6: =HOUR(Table3[[#This Row],[Transaction_Time]]) -> 14 | F6: Amazon Pay | G6: CUST513285 | H6: 45-54 | I6: Female | J6: Gujarat | K6: Surat | L6: Data Tutorials | M6: Education | N6: Online Shopping | O6: UPI ID | P6: Punjab National Bank | Q6: 165.15 | R6: 15.37 | S6: 0 | T6: Success | V6: iOS | W6: 25 | X6: No
A7: UPI202605P2_0000006 | B7: 46143 | C7: =TEXT(Table3[[#This Row],[Transaction_Date]],"dddd") -> Friday | D7: 11:32:38 | E7: =HOUR(Table3[[#This Row],[Transaction_Time]]) -> 11 | F7: Google Pay | G7: CUST980289 | H7: 45-54 | I7: Female | J7: Gujarat | K7: Surat | L7: Jio | M7: Recharge & Bills | N7: P2M | O7: UPI ID | P7: SBI | Q7: 135.39 | R7: 0 | S7: 2.79 | T7: Success | V7: Android | W7: 75 | X7: No
A8: UPI202605P2_0000007 | B8: 46157 | C8: =TEXT(Table3[[#This Row],[Transaction_Date]],"dddd") -> Friday | D8: 07:12:45 | E8: =HOUR(Table3[[#This Row],[Transaction_Time]]) -> 7 | F8: Cred Pay | G8: CUST245668 | H8: 18-24 | I8: Male | J8: Madhya Pradesh | K8: Jabalpur | L8: Zomato | M8: Food & Dining | N8: P2M | O8: QR Scan | P8: HDFC Bank | Q8: 169.57 | R8: 15.45 | S8: 0 | T8: Success | V8: Android | W8: 81 | X8: No
A9: UPI202605P2_0000008 | B9: 46160 | C9: =TEXT(Table3[[#This Row],[Transaction_Date]],"dddd") -> Monday | D9: 18:34:26 | E9: =HOUR(Table3[[#This Row],[Transaction_Time]]) -> 18 | F9: PhonePe | G9: CUST780035 | H9: 55+ | I9: Male | J9: Rajasthan | K9: Udaipur | L9: Myntra | M9: Shopping | N9: P2M | O9: UPI ID | P9: HDFC Bank | Q9: 936.58 | R9: 0 | S9: 3.76 | T9: Success | V9: Android | W9: 23 | X9: No
A10: UPI202605P2_0000009 | B10: 46144 | C10: =TEXT(Table3[[#This Row],[Transaction_Date]],"dddd") -> Saturday | D10: 11:37:17 | E10: =HOUR(Table3[[#This Row],[Transaction_Time]]) -> 11 | F10: PhonePe | G10: CUST954499 | H10: 25-34 | I10: Female | J10: West Bengal | K10: Kolkata | L10: McDonalds | M10: Food & Dining | N10: P2M | O10: UPI ID | P10: Kotak Mahindra Bank | Q10: 316.48 | R10: 0 | S10: 7.64 | T10: Success | V10: Android | W10: 88 | X10: No
A11: UPI202605P2_0000010 | B11: 46171 | C11: =TEXT(Table3[[#This Row],[Transaction_Date]],"dddd") -> Friday | D11: 19:00:48 | E11: =HOUR(Table3[[#This Row],[Transaction_Time]]) -> 19 | F11: PhonePe | G11: CUST556644 | H11: 35-44 | I11: Female | J11: Tamil Nadu | K11: Madurai | L11: JioMart | M11: Grocery | N11: Online Shopping | O11: Bank Account | P11: ICICI Bank | Q11: 612.77 | R11: 0 | S11: 0 | T11: Success | V11: Android | W11: 81 | X11: No
A12: UPI202605P2_0000011 | B12: 46151 | C12: =TEXT(Table3[[#This Row],[Transaction_Date]],"dddd") -> Saturday | D12: 19:44:27 | E12: =HOUR(Table3[[#This Row],[Transaction_Time]]) -> 19 | F12: PhonePe | G12: CUST103076 | H12: 18-24 | I12: Female | J12: Karnataka | K12: Mysuru | L12: Amazon Prime | M12: Entertainment | N12: Online Shopping | O12: Bank Account | P12: SBI | Q12: 457.86 | R12: 0 | S12: 5.23 | T12: Success | V12: Android | W12: 2 | X12: No
A13: UPI202605P2_0000012 | B13: 46149 | C13: =TEXT(Table3[[#This Row],[Transaction_Date]],"dddd") -> Thursday | D13: 13:09:13 | E13: =HOUR(Table3[[#This Row],[Transaction_Time]]) -> 13 | F13: PhonePe | G13: CUST163783 | H13: 18-24 | I13: Female | J13: Rajasthan | K13: Jodhpur | L13: BigBasket | M13: Grocery | N13: P2M | O13: Bank Account | P13: Canara Bank | Q13: 175.83 | R13: 49.99 | S13: 0 | T13: Success | V13: Android | W13: 58 | X13: No
... A48: UPI202605P2_0000047 | B48: 46152 | C48: =TEXT(Table3[[#This Row],[Transaction_Date]],"dddd") -> Sunday | D48: 13:29:33 | E48: =HOUR(Table3[[#This Row],[Transaction_Time]]) -> 13 | F48: PhonePe | G48: CUST367974 | H48: 25-34 | I48: Male | J48: Karnataka | K48: Mangaluru | L48: Tata Play | M48: Recharge & Bills | N48: P2M | O48: QR Scan | P48: HDFC Bank | Q48: 246.13 | R48: 0 | S48: 0 | T48: Success | V48: Android | W48: 10 | X48: No
A49: UPI202605P2_0000048 | B49: 46159 | C49: =TEXT(Table3[[#This Row],[Transaction_Date]],"dddd") -> Sunday | D49: 12:35:55 | E49: =HOUR(Table3[[#This Row],[Transaction_Time]]) -> 12 | F49: Paytm | G49: CUST873091 | H49: 18-24 | I49: Female | J49: Karnataka | K49: Mangaluru | L49: Broadband Bill | M49: Utilities | N49: P2M | O49: QR Scan | P49: Axis Bank | Q49: 626.93 | R49: 0 | S49: 2.1 | T49: Failed | U49: Transaction Timeout | V49: Android | W49: 26 | X49: No
A50: UPI202605P2_0000049 | B50: 46156 | C50: =TEXT(Table3[[#This Row],[Transaction_Date]],"dddd") -> Thursday | D50: 21:43:46 | E50: =HOUR(Table3[[#This Row],[Transaction_Time]]) -> 21 | F50: Amazon Pay | G50: CUST142917 | H50: 18-24 | I50: Male | J50: Tamil Nadu | K50: Coimbatore | L50: Netflix | M50: Entertainment | N50: Bill Payment | O50: QR Scan | P50: HDFC Bank | Q50: 172.82 | R50: 0 | S50: 0 | T50: Success | V50: iOS | W50: 33 | X50: No
A51: UPI202605P2_0000050 | B51: 46157 | C51: =TEXT(Table3[[#This Row],[Transaction_Date]],"dddd") -> Friday | D51: 09:56:34 | E51: =HOUR(Table3[[#This Row],[Transaction_Time]]) -> 9 | F51: PhonePe | G51: CUST630621 | H51: 18-24 | I51: Female | J51: Madhya Pradesh | K51: Jabalpur | L51: Dominos | M51: Food & Dining | N51: Wallet Transfer | O51: Mobile Number | P51: Axis Bank | Q51: 1891.52 | R51: 0 | S51: 0 | T51: Success | V51: Android | W51: 33 | X51: No
A52: UPI202605P2_0000051 | B52: 46159 | C52: =TEXT(Table3[[#This Row],[Transaction_Date]],"dddd") -> Sunday | D52: 19:49:41 | E52: =HOUR(Table3[[#This Row],[Transaction_Time]]) -> 19 | F52: PhonePe | G52: CUST245463 | H52: 25-34 | I52: Female | J52: Gujarat | K52: Ahmedabad | L52: Credit Card Bill | M52: Financial Services | N52: Bill Payment | O52: Collect Request | P52: ICICI Bank | Q52: 107.66 | R52: 0 | S52: 5.01 | T52: Success | V52: Android | W52: 62 | X52: No
A53: UPI202605P2_0000052 | B53: 46149 | C53: =TEXT(Table3[[#This Row],[Transaction_Date]],"dddd") -> Thursday | D53: 13:18:27 | E53: =HOUR(Table3[[#This Row],[Transaction_Time]]) -> 13 | F53: PhonePe | G53: CUST254011 | H53: 18-24 | I53: Male | J53: Uttar Pradesh | K53: Varanasi | L53: Gas Bill | M53: Utilities | N53: P2M | O53: QR Scan | P53: Kotak Mahindra Bank | Q53: 6623.29 | R53: 0 | S53: 0 | T53: Success | V53: Android | W53: 54 | X53: No
A54: UPI202605P2_0000053 | B54: 46151 | C54: =TEXT(Table3[[#This Row],[Transaction_Date]],"dddd") -> Saturday | D54: 10:00:46 | E54: =HOUR(Table3[[#This Row],[Transaction_Time]]) -> 10 | F54: PhonePe | G54: CUST816202 | H54: 25-34 | I54: Female | J54: Uttar Pradesh | K54: Varanasi | L54: Unacademy | M54: Education | N54: P2M | O54: UPI ID | P54: Bank of Baroda | Q54: 575.35 | R54: 42.09 | S54: 3.58 | T54: Success | V54: Android | W54: 85 | X54: No
A55: UPI202605P2_0000054 | B55: 46167 | C55: =TEXT(Table3[[#This Row],[Transaction_Date]],"dddd") -> Monday | D55: 20:16:32 | E55: =HOUR(Table3[[#This Row],[Transaction_Time]]) -> 20 | F55: PhonePe | G55: CUST479261 | H55: 45-54 | I55: Female | J55: Telangana | K55: Hyderabad | L55: Practo | M55: Healthcare | N55: Bill Payment | O55: QR Scan | P55: HDFC Bank | Q55: 51.31 | R55: 31.58 | S55: 0 | T55: Success | V55: Android | W55: 40 | X55: No
A56: UPI202605P2_0000055 | B56: 46147 | C56: =TEXT(Table3[[#This Row],[Transaction_Date]],"dddd") -> Tuesday | D56: 19:32:58 | E56: =HOUR(Table3[[#This Row],[Transaction_Time]]) -> 19 | F56: PhonePe | G56: CUST324703 | H56: 25-34 | I56: Male | J56: West Bengal | K56: Kolkata | L56: IRCTC | M56: Travel | N56: P2M | O56: Mobile Number | P56: SBI | Q56: 84.25 | R56: 0 | S56: 0 | T56: Success | V56: Android | W56: 45 | X56: No
A57: UPI202605P2_0000056 | B57: 46156 | C57: =TEXT(Table3[[#This Row],[Transaction_Date]],"dddd") -> Thursday | D57: 09:40:19 | E57: =HOUR(Table3[[#This Row],[Transaction_Time]]) -> 9 | F57: Paytm | G57: CUST941782 | H57: 18-24 | I57: Male | J57: Tamil Nadu | K57: Coimbatore | L57: Amazon Prime | M57: Entertainment | N57: P2M | O57: QR Scan | P57: SBI | Q57: 998.9 | R57: 0 | S57: 2.58 | T57: Failed | U57: Beneficiary Bank Offline | V57: iOS | W57: 97 | X57: No
A58: UPI202605P2_0000057 | B58: 46159 | C58: =TEXT(Table3[[#This Row],[Transaction_Date]],"dddd") -> Sunday | D58: 20:32:38 | E58: =HOUR(Table3[[#This Row],[Transaction_Time]]) -> 20 | F58: Google Pay | G58: CUST784614 | H58: 25-34 | I58: Female | J58: Maharashtra | K58: Mumbai | L58: Zomato | M58: Food & Dining | N58: P2M | O58: UPI ID | P58: SBI | Q58: 1454.46 | R58: 0 | S58: 0 | T58: Success | V58: Android | W58: 94 | X58: No
A59: UPI202605P2_0000058 | B59: 46162 | C59: =TEXT(Table3[[#This Row],[Transaction_Date]],"dddd") -> Wednesday | D59: 11:23:48 | E59: =HOUR(Table3[[#This Row],[Transaction_Time]]) -> 11 | F59: Google Pay | G59: CUST209130 | H59: 18-24 | I59: Male | J59: Karnataka | K59: Bengaluru | L59: Jio | M59: Recharge & Bills | N59: Wallet Transfer | O59: QR Scan | P59: Canara Bank | Q59: 895.69 | R59: 0 | S59: 7.79 | T59: Success | V59: Android | W59: 66 | X59: No
A60: UPI202605P2_0000059 | B60: 46165 | C60: =TEXT(Table3[[#This Row],[Transaction_Date]],"dddd") -> Saturday | D60: 10:49:59 | E60: =HOUR(Table3[[#This Row],[Transaction_Time]]) -> 10 | F60: PhonePe | G60: CUST105818 | H60: 25-34 | I60: Female | J60: Rajasthan | K60: Udaipur | L60: Local Kirana | M60: Grocery | N60: P2M | O60: Bank Account | P60: HDFC Bank | Q60: 311.52 | R60: 0 | S60: 4.42 | T60: Success | V60: iOS | W60: 38 | X60: No
A61: UPI202605P2_0000060 | B61: 46152 | C61: =TEXT(Table3[[#This Row],[Transaction_Date]],"dddd") -> Sunday | D61: 16:00:38 | E61: =HOUR(Table3[[#This Row],[Transaction_Time]]) -> 16 | F61: Google Pay | G61: CUST610999 | H61: 45-54 | I61: Male | J61: Rajasthan | K61: Jodhpur | L61: MSEB | M61: Recharge & Bills | N61: P2M | O61: Mobile Number | P61: Axis Bank | Q61: 743.71 | R61: 62.53 | S61: 0 | T61: Success | V61: Android | W61: 87 | X61: No
A62: UPI202605P2_0000061 | B62: 46154 | C62: =TEXT(Table3[[#This Row],[Transaction_Date]],"dddd") -> Tuesday | D62: 13:01:07 | E62: =HOUR(Table3[[#This Row],[Transaction_Time]]) -> 13 | F62: Google Pay | G62: CUST369990 | H62: 35-44 | I62: Male | J62: Delhi | K62: Rohini | L62: MedPlus | M62: Healthcare | N62: Bill Payment | O62: UPI ID | P62: Axis Bank | Q62: 643.23 | R62: 0 | S62: 5.64 | T62: Success | V62: Android | W62: 82 | X62: No
A63: UPI202605P2_0000062 | B63: 46163 | C63: =TEXT(Table3[[#This Row],[Transaction_Date]],"dddd") -> Thursday | D63: 21:56:53 | E63: =HOUR(Table3[[#This Row],[Transaction_Time]]) -> 21 | F63: Cred Pay | G63: CUST607898 | H63: 35-44 | I63: Male | J63: Rajasthan | K63: Kota | L63: MedPlus | M63: Healthcare | N63: Bill Payment | O63: Bank Account | P63: Kotak Mahindra Bank | Q63: 426.79 | R63: 0 | S63: 0 | T63: Success | V63: Android | W63: 14 | X63: No
A64: UPI202605P2_0000063 | B64: 46152 | C64: =TEXT(Table3[[#This Row],[Transaction_Date]],"dddd") -> Sunday | D64: 19:15:03 | E64: =HOUR(Table3[[#This Row],[Transaction_Time]]) -> 19 | F64: Google Pay | G64: CUST737557 | H64: 35-44 | I64: Male | J64: West Bengal | K64: Kolkata | L64: Society Maintenance | M64: Utilities | N64: Bill Payment | O64: UPI ID | P64: Kotak Mahindra Bank | Q64: 156.99 | R64: 0 | S64: 0 | T64: Success | V64: Android | W64: 14 | X64: No
A65: UPI202605P2_0000064 | B65: 46148 | C65: =TEXT(Table3[[#This Row],[Transaction_Date]],"dddd") -> Wednesday | D65: 11:36:05 | E65: =HOUR(Table3[[#This Row],[Transaction_Time]]) -> 11 | F65: PhonePe | G65: CUST347727 | H65: 25-34 | I65: Male | J65: Madhya Pradesh | K65: Bhopal | L65: Indian Oil | M65: Fuel | N65: Online Shopping | O65: UPI ID | P65: Axis Bank | Q65: 2532.54 | R65: 0 | S65: 0 | T65: Success | V65: Android | W65: 99 | X65: No
A66: UPI202605P2_0000065 | B66: 46150 | C66: =TEXT(Table3[[#This Row],[Transaction_Date]],"dddd") -> Friday | D66: 09:31:52 | E66: =HOUR(Table3[[#This Row],[Transaction_Time]]) -> 9 | F66: PhonePe | G66: CUST703894 | H66: 25-34 | I66: Female | J66: Madhya Pradesh | K66: Jabalpur | L66: Coursera | M66: Education | N66: Wallet Transfer | O66: UPI ID | P66: HDFC Bank | Q66: 339.76 | R66: 0 | S66: 1.24 | T66: Success | V66: Android | W66: 30 | X66: No
A67: UPI202605P2_0000066 | B67: 46173 | C67: =TEXT(Table3[[#This Row],[Transaction_Date]],"dddd") -> Sunday | D67: 08:48:34 | E67: =HOUR(Table3[[#This Row],[Transaction_Time]]) -> 8 | F67: PhonePe | G67: CUST105016 | H67: 18-24 | I67: Male | J67: Telangana | K67: Nizamabad | L67: Local Kirana | M67: Grocery | N67: P2P | O67: QR Scan | P67: Canara Bank | Q67: 206.55 | R67: 41.31 | S67: 0 | T67: Success | V67: Android | W67: 67 | X67: No
A68: UPI202605P2_0000067 | B68: 46144 | C68: =TEXT(Table3[[#This Row],[Transaction_Date]],"dddd") -> Saturday | D68: 19:08:42 | E68: =HOUR(Table3[[#This Row],[Transaction_Time]]) -> 19 | F68: PhonePe | G68: CUST181753 | H68: 18-24 | I68: Female | J68: West Bengal | K68: Howrah | L68: Spotify | M68: Entertainment | N68: P2P | O68: QR Scan | P68: Kotak Mahindra Bank | Q68: 508.24 | R68: 0 | S68: 0 | T68: Failed | U68: Transaction Timeout | V68: Android | W68: 91 | X68: No
A69: UPI202605P2_0000068 | B69: 46166 | C69: =TEXT(Table3[[#This Row],[Transaction_Date]],"dddd") -> Sunday | D69: 15:35:10 | E69: =HOUR(Table3[[#This Row],[Transaction_Time]]) -> 15 | F69: Google Pay | G69: CUST165329 | H69: 25-34 | I69: Female | J69: Telangana | K69: Hyderabad | L69: Society Maintenance | M69: Utilities | N69: P2M | O69: Bank Account | P69: HDFC Bank | Q69: 377.74 | R69: 0 | S69: 0 | T69: Success | V69: Android | W69: 62 | X69: No
A70: UPI202605P2_0000069 | B70: 46143 | C70: =TEXT(Table3[[#This Row],[Transaction_Date]],"dddd") -> Friday | D70: 12:55:38 | E70: =HOUR(Table3[[#This Row],[Transaction_Time]]) -> 12 | F70: PhonePe | G70: CUST536554 | H70: 35-44 | I70: Female | J70: Uttar Pradesh | K70: Lucknow | L70: Reliance Fresh | M70: Grocery | N70: Recharge | O70: UPI ID | P70: Axis Bank | Q70: 810.16 | R70: 0 | S70: 0 | T70: Success | V70: Android | W70: 41 | X70: No
A71: UPI202605P2_0000070 | B71: 46164 | C71: =TEXT(Table3[[#This Row],[Transaction_Date]],"dddd") -> Friday | D71: 14:13:59 | E71: =HOUR(Table3[[#This Row],[Transaction_Time]]) -> 14 | F71: Google Pay | G71: CUST119303 | H71: 25-34 | I71: Female | J71: Maharashtra | K71: Pune | L71: Tata Play | M71: Recharge & Bills | N71: P2P | O71: UPI ID | P71: Canara Bank | Q71: 262.07 | R71: 0 | S71: 0 | T71: Success | V71: Android | W71: 47 | X71: No
A72: UPI202605P2_0000071 | B72: 46167 | C72: =TEXT(Table3[[#This Row],[Transaction_Date]],"dddd") -> Monday | D72: 16:46:44 | E72: =HOUR(Table3[[#This Row],[Transaction_Time]]) -> 16 | F72: BHIM | G72: CUST738697 | H72: 25-34 | I72: Male | J72: Delhi | K72: New Delhi | L72: Tata Play | M72: Recharge & Bills | N72: P2P | O72: QR Scan | P72: Kotak Mahindra Bank | Q72: 328.6 | R72: 0 | S72: 0 | T72: Success | V72: Android | W72: 1 | X72: No
A73: UPI202605P2_0000072 | B73: 46166 | C73: =TEXT(Table3[[#This Row],[Transaction_Date]],"dddd") -> Sunday | D73: 11:19:25 | E73: =HOUR(Table3[[#This Row],[Transaction_Time]]) -> 11 | F73: PhonePe | G73: CUST347004 | H73: 25-34 | I73: Male | J73: Telangana | K73: Warangal | L73: Netmeds | M73: Healthcare | N73: P2M | O73: UPI ID | P73: Kotak Mahindra Bank | Q73: 382.27 | R73: 0 | S73: 1.31 | T73: Success | V73: Android | W73: 37 | X73: No
A74: UPI202605P2_0000073 | B74: 46163 | C74: =TEXT(Table3[[#This Row],[Transaction_Date]],"dddd") -> Thursday | D74: 23:41:23 | E74: =HOUR(Table3[[#This Row],[Transaction_Time]]) -> 23 | F74: Google Pay | G74: CUST470023 | H74: 35-44 | I74: Male | J74: Karnataka | K74: Hubballi | L74: Cafe Coffee Day | M74: Food & Dining | N74: P2P | O74: Collect Request | P74: Bank of Baroda | Q74: 549.83 | R74: 0 | S74: 5.16 | T74: Success | V74: iOS | W74: 99 | X74: Yes
...

Sheet Dashboard

Sheet pivot table
A3: Count of Transaction_ID | B3: Sum of Amount_INR | C3: Sum of Cashback_INR
A4: 5000 | B4: 4225721.7 | C4: 33561.75
A6: =GETPIVOTDATA("Count of Transaction_ID",$A$3) -> 5000 | B6: =GETPIVOTDATA("Sum of Amount_INR",$A$3) -> 4225721.7 | C6: =GETPIVOTDATA("Sum of Cashback_INR",$A$3) -> 33561.75
B7: =B6/1000000 -> 4.2257217 | C7: =C6/10000 -> 3.356175
A11: Row Labels | B11: Count of Transaction_ID
A12: Failed | B12: 339
A13: Pending | B13: 115
A14: Success | B14: 4546 | C14: =GETPIVOTDATA("Transaction_ID",$A$11,"Status","Success") -> 4546 | D14: =C14/A6 -> 0.9092
A15: Grand Total | B15: 5000
A18: Row Labels | B18: Count of Transaction_ID
A19: No | B19: 4856
A20: Yes | B20: 144 | C20: =GETPIVOTDATA("Transaction_ID",$A$18,"Is_Suspected_Fraud","Yes") -> 144
A21: Grand Total | B21: 5000
A24: Row Labels | B24: Sum of Amount_INR
A25: 46143 | B25: 128206.46 | D25: Day | E25: Amount | F25: Amount 1
A26: 46144 | B26: 141034.66 | D26: =DAY(A25) -> 1 | E26: =GETPIVOTDATA("Amount_INR",$A$24,"Transaction_Date",A25)/100000 -> 1.2820646 | F26: =GETPIVOTDATA("Amount_INR",$A$24,"Transaction_Date",A25)/100000 -> 1.2820646
A27: 46145 | B27: 134058.36 | D27: =DAY(A26) -> 2 | E27: =GETPIVOTDATA("Amount_INR",$A$24,"Transaction_Date",A26)/100000 -> 1.4103466 | F27: =GETPIVOTDATA("Amount_INR",$A$24,"Transaction_Date",A26)/100000 -> 1.4103466
A28: 46146 | B28: 147248.15 | D28: =DAY(A27) -> 3 | E28: =GETPIVOTDATA("Amount_INR",$A$24,"Transaction_Date",A27)/100000 -> 1.3405836 | F28: =GETPIVOTDATA("Amount_INR",$A$24,"Transaction_Date",A27)/100000 -> 1.3405836
A29: 46147 | B29: 133180.76 | D29: =DAY(A28) -> 4 | E29: =GETPIVOTDATA("Amount_INR",$A$24,"Transaction_Date",A28)/100000 -> 1.4724815 | F29: =GETPIVOTDATA("Amount_INR",$A$24,"Transaction_Date",A28)/100000 -> 1.4724815
A30: 46148 | B30: 138179.21 | D30: =DAY(A29) -> 5 | E30: =GETPIVOTDATA("Amount_INR",$A$24,"Transaction_Date",A29)/100000 -> 1.3318076 | F30: =GETPIVOTDATA("Amount_INR",$A$24,"Transaction_Date",A29)/100000 -> 1.3318076
A31: 46149 | B31: 145328.88 | D31: =DAY(A30) -> 6 | E31: =GETPIVOTDATA("Amount_INR",$A$24,"Transaction_Date",A30)/100000 -> 1.3817921 | F31: =GETPIVOTDATA("Amount_INR",$A$24,"Transaction_Date",A30)/100000 -> 1.3817921
A32: 46150 | B32: 129567.08 | D32: =DAY(A31) -> 7 | E32: =GETPIVOTDATA("Amount_INR",$A$24,"Transaction_Date",A31)/100000 -> 1.4532888 | F32: =GETPIVOTDATA("Amount_INR",$A$24,"Transaction_Date",A31)/100000 -> 1.4532888
A33: 46151 | B33: 165348.89 | D33: =DAY(A32) -> 8 | E33: =GETPIVOTDATA("Amount_INR",$A$24,"Transaction_Date",A32)/100000 -> 1.2956708 | F33: =GETPIVOTDATA("Amount_INR",$A$24,"Transaction_Date",A32)/100000 -> 1.2956708
A34: 46152 | B34: 122855.69 | D34: =DAY(A33) -> 9 | E34: =GETPIVOTDATA("Amount_INR",$A$24,"Transaction_Date",A33)/100000 -> 1.6534889 | F34: =GETPIVOTDATA("Amount_INR",$A$24,"Transaction_Date",A33)/100000 -> 1.6534889
A35: 46153 | B35: 123097.25 | D35: =DAY(A34) -> 10 | E35: =GETPIVOTDATA("Amount_INR",$A$24,"Transaction_Date",A34)/100000 -> 1.2285569 | F35: =GETPIVOTDATA("Amount_INR",$A$24,"Transaction_Date",A34)/100000 -> 1.2285569
A36: 46154 | B36: 120525.93 | D36: =DAY(A35) -> 11 | E36: =GETPIVOTDATA("Amount_INR",$A$24,"Transaction_Date",A35)/100000 -> 1.2309725 | F36: =GETPIVOTDATA("Amount_INR",$A$24,"Transaction_Date",A35)/100000 -> 1.2309725
A37: 46155 | B37: 120124.95 | D37: =DAY(A36) -> 12 | E37: =GETPIVOTDATA("Amount_INR",$A$24,"Transaction_Date",A36)/100000 -> 1.2052593 | F37: =GETPIVOTDATA("Amount_INR",$A$24,"Transaction_Date",A36)/100000 -> 1.2052593
... A55: 46173 | B55: 152703.4 | D55: =DAY(A54) -> 30 | E55: =GETPIVOTDATA("Amount_INR",$A$24,"Transaction_Date",A54)/100000 -> 1.1934783 | F55: =GETPIVOTDATA("Amount_INR",$A$24,"Transaction_Date",A54)/100000 -> 1.1934783
A56: Grand Total | B56: 4225721.7 | D56: =DAY(A55) -> 31 | E56: =GETPIVOTDATA("Amount_INR",$A$24,"Transaction_Date",A55)/100000 -> 1.527034 | F56: =GETPIVOTDATA("Amount_INR",$A$24,"Transaction_Date",A55)/100000 -> 1.527034
A60: Row Labels | B60: Sum of Amount_INR
A61: Amazon Pay | B61: 260802.52
A62: BHIM | B62: 158520.99
A63: Cred Pay | B63: 134492.88
A64: Google Pay | B64: 920905.9
A65: Paytm | B65: 637060.75
A66: PhonePe | B66: 2006465.7
A67: WhatsApp Pay | B67: 107473.02
A72: Row Labels | B72: Sum of Amount_INR
A73: PhonePe | B73: 0.474822
A74: Google Pay | B74: 0.21792867
...

Sheet Sheet3
A2: ='pivot table'!A73 -> PhonePe | B2: =GETPIVOTDATA("Amount_INR",'pivot table'!$A$72,"UPI_App",A2) -> 0.474822
A3: ='pivot table'!A74 -> Google Pay | B3: =GETPIVOTDATA("Amount_INR",'pivot table'!$A$72,"UPI_App",A3) -> 0.21792867
A4: ='pivot table'!A75 -> Paytm | B4: =GETPIVOTDATA("Amount_INR",'pivot table'!$A$72,"UPI_App",A4) -> 0.15075786
A5: ='pivot table'!A76 -> Amazon Pay | B5: =GETPIVOTDATA("Amount_INR",'pivot table'!$A$72,"UPI_App",A5) -> 0.061717865
A6: ='pivot table'!A77 -> BHIM | B6: =GETPIVOTDATA("Amount_INR",'pivot table'!$A$72,"UPI_App",A6) -> 0.037513353
A7: ='pivot table'!A78 -> Cred Pay | B7: =GETPIVOTDATA("Amount_INR",'pivot table'!$A$72,"UPI_App",A7) -> 0.031827198
A8: ='pivot table'!A79 -> WhatsApp Pay | B8: =GETPIVOTDATA("Amount_INR",'pivot table'!$A$72,"UPI_App",A8) -> 0.025433057
A11: ='pivot table'!A83 -> Success | B11: =GETPIVOTDATA("Amount_INR",'pivot table'!$A$82,"Status",Sheet3!A11) -> 0.90920187
A12: ='pivot table'!A84 -> Failed | B12: =GETPIVOTDATA("Amount_INR",'pivot table'!$A$82,"Status",Sheet3!A12) -> 0.070434371
A13: ='pivot table'!A85 -> Pending | B13: =GETPIVOTDATA("Amount_INR",'pivot table'!$A$82,"Status",Sheet3!A13) -> 0.020363764
E20: Sum of Amount_INR | F20: Column Labels
E21: Row Labels | F21: 0 | G21: 1 | H21: 2 | I21: 3 | J21: 4 | K21: 5 | L21: 6 | M21: 7 | N21: 8 | O21: 9 | P21: 10 | Q21: 11 | R21: 12 | S21: 13 | T21: 14 | U21: 15 | V21: 16 | W21: 17 | X21: 18 | Y21: 19 | Z21: 20 | AA21: 21 | AB21: 22 | AC21: 23
E22: Sunday | G22: 91.58 | J22: 81.28 | L22: 1885.88 | M22: 7049.53 | N22: 32800.42 | O22: 25421.71 | P22: 77531.44 | Q22: 38182.39 | R22: 68664.53 | S22: 56108.2 | T22: 55596.22 | U22: 78874.23 | V22: 29382.65 | W22: 52104.01 | X22: 94137.6 | Y22: 76505.09 | Z22: 65625.29 | AA22: 22305.91 | AB22: 20787.42 | AC22: 1123.21
E23: Monday | F23: 276.4 | G23: 3311.85 | J23: 234.52 | L23: 1185.69 | M23: 7459.07 | N23: 20340.69 | O23: 22865.25 | P23: 38380.48 | Q23: 27690.51 | R23: 42243.29 | S23: 33792.29 | T23: 39410.07 | U23: 51425.68 | V23: 31706.57 | W23: 28817.93 | X23: 44663.32 | Y23: 45136.69 | Z23: 40648.83 | AA23: 30604.94 | AB23: 6964.64 | AC23: 659.27
E24: Tuesday | F24: 986.81 | H24: 1810.01 | J24: 402.45 | K24: 392.58 | L24: 773.35 | M24: 3009.05 | N24: 26589.82 | O24: 41959.89 | P24: 32912.14 | Q24: 21366.28 | R24: 38694.03 | S24: 20107.35 | T24: 30651.5 | U24: 46206 | V24: 27336.58 | W24: 29189.58 | X24: 68458.56 | Y24: 60389.46 | Z24: 32121.48 | AA24: 17822.97 | AB24: 4827.47 | AC24: 2708.07
E25: Wednesday | F25: 1643.85 | H25: 780.75 | I25: 368.58 | J25: 1167.09 | K25: 2409.86 | L25: 1063.73 | M25: 5203.16 | N25: 9393.34 | O25: 45865.54 | P25: 21343.51 | Q25: 40467.78 | R25: 33681.43 | S25: 39005.04 | T25: 22143.57 | U25: 27692.71 | V25: 28671.61 | W25: 34630.26 | X25: 50112.48 | Y25: 54524.65 | Z25: 31833.04 | AA25: 23635.3 | AB25: 9805.51 | AC25: 4149.56
E26: Thursday | F26: 1489.87 | G26: 472.88 | I26: 403.46 | K26: 3310.4 | L26: 5605.63 | M26: 5469.75 | N26: 27487.99 | O26: 39369.06 | P26: 38272.39 | Q26: 30630.13 | R26: 38294.57 | S26: 36331.18 | T26: 30024.43 | U26: 16200.16 | V26: 23779.29 | W26: 55787.34 | X26: 56655.98 | Y26: 66821.51 | Z26: 29341.33 | AA26: 14221.31 | AB26: 11269.96 | AC26: 4376.31
E27: Friday | G27: 404.82 | K27: 384.98 | L27: 7649.65 | M27: 11631.48 | N27: 11134.48 | O27: 44261.05 | P27: 30785.4 | Q27: 32501.79 | R27: 52485.2 | S27: 60014.2 | T27: 30546.46 | U27: 59207.89 | V27: 37282.33 | W27: 47746.14 | X27: 60099.7 | Y27: 66813.54 | Z27: 77422.14 | AA27: 41838.66 | AB27: 15407 | AC27: 3132.31
E28: Saturday | F28: 209.73 | G28: 1225.02 | H28: 1093.38 | I28: 133.2 | L28: 3472.7 | M28: 9279.89 | N28: 19754.21 | O28: 54873.14 | P28: 39140.4 | Q28: 47883.26 | R28: 45056.67 | S28: 49031.98 | T28: 35456.62 | U28: 40951.45 | V28: 29461.6 | W28: 45882.8 | X28: 76041.04 | Y28: 54643.05 | Z28: 74332.44 | AA28: 30416.18 | AB28: 17692.75 | AC28: 2941.7
B33: ='pivot table'!D90 -> Tamil Nadu | C33: =GETPIVOTDATA("Amount_INR",'pivot table'!$A$89,"State",B33)/100000 -> 4.8386428
B34: ='pivot table'!D91 -> Delhi | C34: =GETPIVOTDATA("Amount_INR",'pivot table'!$A$89,"State",B34)/100000 -> 4.8224036
B35: ='pivot table'!D92 -> Karnataka | C35: =GETPIVOTDATA("Amount_INR",'pivot table'!$A$89,"State",B35)/100000 -> 4.4936873
B36: ='pivot table'!D93 -> Gujarat | C36: =GETPIVOTDATA("Amount_INR",'pivot table'!$A$89,"State",B36)/100000 -> 4.2309654
B37: ='pivot table'!D94 -> Madhya Pradesh | C37: =GETPIVOTDATA("Amount_INR",'pivot table'!$A$89,"State",B37)/100000 -> 4.2148056
B38: ='pivot table'!D95 -> Telangana | C38: =GETPIVOTDATA("Amount_INR",'pivot table'!$A$89,"State",B38)/100000 -> 4.176339
B39: ='pivot table'!D96 -> Uttar Pradesh | C39: =GETPIVOTDATA("Amount_INR",'pivot table'!$A$89,"State",B39)/100000 -> 4.1579512
B40: ='pivot table'!D97 -> West Bengal | C40: =GETPIVOTDATA("Amount_INR",'pivot table'!$A$89,"State",B40)/100000 -> 3.9833879
B41: ='pivot table'!D98 -> Rajasthan | C41: =GETPIVOTDATA("Amount_INR",'pivot table'!$A$89,"State",B41)/100000 -> 3.9827426
B42: ='pivot table'!D99 -> Maharashtra | C42: =GETPIVOTDATA("Amount_INR",'pivot table'!$A$89,"State",B42)/100000 -> 3.3562917
F46: Sum of Amount_INR | G46: Column Labels
F47: Row Labels | G47: 0 | H47: 1 | I47: 2 | J47: 3 | K47: 4 | L47: 5 | M47: 6 | N47: 7 | O47: 8 | P47: 9 | Q47: 10 | R47: 11 | S47: 12 | T47: 13 | U47: 14 | V47: 15 | W47: 16 | X47: 17 | Y47: 18 | Z47: 19 | AA47: 20 | AB47: 21 | AC47: 22 | AD47: 23
F48: Sunday | H48: 91.58 | K48: 81.28 | M48: 1885.88 | N48: 7049.53 | O48: 32800.42 | P48: 25421.71 | Q48: 77531.44 | R48: 38182.39 | S48: 68664.53 | T48: 56108.2 | U48: 55596.22 | V48: 78874.23 | W48: 29382.65 | X48: 52104.01 | Y48: 94137.6 | Z48: 76505.09 | AA48: 65625.29 | AB48: 22305.91 | AC48: 20787.42 | AD48: 1123.21
F49: Monday | G49: 276.4 | H49: 3311.85 | K49: 234.52 | M49: 1185.69 | N49: 7459.07 | O49: 20340.69 | P49: 22865.25 | Q49: 38380.48 | R49: 27690.51 | S49: 42243.29 | T49: 33792.29 | U49: 39410.07 | V49: 51425.68 | W49: 31706.57 | X49: 28817.93 | Y49: 44663.32 | Z49: 45136.69 | AA49: 40648.83 | AB49: 30604.94 | AC49: 6964.64 | AD49: 659.27
F50: Tuesday | G50: 986.81 | I50: 1810.01 | K50: 402.45 | L50: 392.58 | M50: 773.35 | N50: 3009.05 | O50: 26589.82 | P50: 41959.89 | Q50: 32912.14 | R50: 21366.28 | S50: 38694.03 | T50: 20107.35 | U50: 30651.5 | V50: 46206 | W50: 27336.58 | X50: 29189.58 | Y50: 68458.56 | Z50: 60389.46 | AA50: 32121.48 | AB50: 17822.97 | AC50: 4827.47 | AD50: 2708.07
F51: Wednesday | G51: 1643.85 | I51: 780.75 | J51: 368.58 | K51: 1167.09 | L51: 2409.86 | M51: 1063.73 | N51: 5203.16 | O51: 9393.34 | P51: 45865.54 | Q51: 21343.51 | R51: 40467.78 | S51: 33681.43 | T51: 39005.04 | U51: 22143.57 | V51: 27692.71 | W51: 28671.61 | X51: 34630.26 | Y51: 50112.48 | Z51: 54524.65 | AA51: 31833.04 | AB51: 23635.3 | AC51: 9805.51 | AD51: 4149.56
F52: Thursday | G52: 1489.87 | H52: 472.88 | J52: 403.46 | L52: 3310.4 | M52: 5605.63 | N52: 5469.75 | O52: 27487.99 | P52: 39369.06 | Q52: 38272.39 | R52: 30630.13 | S52: 38294.57 | T52: 36331.18 | U52: 30024.43 | V52: 16200.16 | W52: 23779.29 | X52: 55787.34 | Y52: 56655.98 | Z52: 66821.51 | AA52: 29341.33 | AB52: 14221.31 | AC52: 11269.96 | AD52: 4376.31
F53: Friday | H53: 404.82 | L53: 384.98 | M53: 7649.65 | N53: 11631.48 | O53: 11134.48 | P53: 44261.05 | Q53: 30785.4 | R53: 32501.79 | S53: 52485.2 | T53: 60014.2 | U53: 30546.46 | V53: 59207.89 | W53: 37282.33 | X53: 47746.14 | Y53: 60099.7 | Z53: 66813.54 | AA53: 77422.14 | AB53: 41838.66 | AC53: 15407 | AD53: 3132.31
F54: Saturday | G54: 209.73 | H54: 1225.02 | I54: 1093.38 | J54: 133.2 | M54: 3472.7 | N54: 9279.89 | O54: 19754.21 | P54: 54873.14 | Q54: 39140.4 | R54: 47883.26 | S54: 45056.67 | T54: 49031.98 | U54: 35456.62 | V54: 40951.45 | W54: 29461.6 | X54: 45882.8 | Y54: 76041.04 | Z54: 54643.05 | AA54: 74332.44 | AB54: 30416.18 | AC54: 17692.75 | AD54: 2941.7
I62: day/hr | J62: =G47 -> 0 | K62: =H47 -> 1 | L62: =I47 -> 2 | M62: =J47 -> 3 | N62: =K47 -> 4 | O62: =L47 -> 5 | P62: =M47 -> 6 | Q62: =N47 -> 7 | ... AD62: =AA47 -> 20 | AF62: =AC47 -> 22
I63: =F48 -> Sunday | J63: =GETPIVOTDATA("Amount_INR",$F$46,"Day",I63,"hour ",$J$62)/10000 -> 0 | K63: =GETPIVOTDATA("Amount_INR",$F$46,"Day",I63,"hour ",$K$62)/10000 -> 0.009158 | L63: =GETPIVOTDATA("Amount_INR",$F$46,"Day",I63,"hour ",$L$62)/10000 -> 0 | M63: =GETPIVOTDATA("Amount_INR",$F$46,"Day",I63,"hour ",$M$62)/10000 -> 0 | N63: =GETPIVOTDATA("Amount_INR",$F$46,"Day",I63,"hour ",$N$62)/10000 -> 0.008128 | O63: =GETPIVOTDATA("Amount_INR",$F$46,"Day",I63,"hour ",$O$62)/10000 -> 0 | P63: =GETPIVOTDATA("Amount_INR",$F$46,"Day",I63,"hour ",$P$62)/10000 -> 0.188588 | Q63: =GETPIVOTDATA("Amount_INR",$F$46,"Day",I63,"hour ",$Q$62)/10000 -> 0.704953 | R63: =GETPIVOTDATA("Amount_INR",$F$46,"Day",I63,"hour ",$R$62)/10000 -> 3.280042 | S63: =GETPIVOTDATA("Amount_INR",$F$46,"Day",I63,"hour ",$S$62)/10000 -> 2.542171 | T63: =GETPIVOTDATA("Amount_INR",$F$46,"Day",I63,"hour ",$T$62)/10000 -> 7.753144 | U63: =GETPIVOTDATA("Amount_INR",$F$46,"Day",I63,"hour ",$U$62)/10000 -> 3.818239 | V63: =GETPIVOTDATA("Amount_INR",$F$46,"Day",I63,"hour ",$V$62)/10000 -> 6.866453 | W63: =GETPIVOTDATA("Amount_INR",$F$46,"Day",I63,"hour ",$W$62)/10000 -> 5.61082 | X63: =GETPIVOTDATA("Amount_INR",$F$46,"Day",I63,"hour ",$X$62)/10000 -> 5.559622 | Y63: =GETPIVOTDATA("Amount_INR",$F$46,"Day",I63,"hour ",$Y$62)/10000 -> 7.887423 | Z63: =GETPIVOTDATA("Amount_INR",$F$46,"Day",I63,"hour ",$Z$62)/10000 -> 2.938265 | AA63: =GETPIVOTDATA("Amount_INR",$F$46,"Day",I63,"hour ",$AA$62)/10000 -> 5.210401 | AB63: =GETPIVOTDATA("Amount_INR",$F$46,"Day",I63,"hour ",$AB$62)/10000 -> 9.41376 | AC63: =GETPIVOTDATA("Amount_INR",$F$46,"Day",I63,"hour ",$AC$62)/10000 -> 7.650509 | AD63: =GETPIVOTDATA("Amount_INR",$F$46,"Day",I63,"hour ",$AD$62)/10000 -> 6.562529 | AE63: =GETPIVOTDATA("Amount_INR",$F$46,"Day",I63,"hour ",$AE$62)/10000 -> 0 | AF63: =GETPIVOTDATA("Amount_INR",$F$46,"Day",I63,"hour ",$AF$62)/10000 -> 2.078742 | AG63: =GETPIVOTDATA("Amount_INR",$F$46,"Day",I63,"hour ",$AG$62)/10000 -> 0
...
